Workbook

Sheet Overview
A1: ATLAS Golden Master — Meridian Securities
A3: Subject: Meridian Securities (composite mid-tier retail brokerage)
A4: Methodology: v1.0 | Status: draft-pending-ratification
A6: This workbook computes one complete assessment with LIVE formulas. Edit a Level on the
A7: Subcomponents sheet (Basic/Developing/Advanced/Frontier, or blank + a State of
A8: NOT_APPLICABLE / NOT_ASSESSED) and q_m, L, B, P and V recompute. Rating-gate bands are
A9: rule-based (non-arithmetic, Methodology §5.2) and shown as computed values on Modules.
A11: DRAFT judgement calls for John to ratify: the subcomponent levels/evidence; the critical
A12: flags; the uniform draft coefficients (α, δ, λ, θ, weights); the power-strength encoding
A13: (None=0, Emerging=0.4, Established=0.7, Wide=1.0); and the rating-gate rule. After an
A14: edit, save, then run scripts/regen_golden_master_json.py to refresh the JSON fixture.
A16: Computed headline: B=0.679138 P=0.271429 L=0.483539 → V=0.478586 (display 47.8586).

Sheet Subcomponents
A1: Module | B1: Subcomponent | C1: Critical | D1: Level | E1: Index | F1: Evidence | G1: State
A2: FRONTEND | B2: PERFORMANCE | C2: Yes | D2: Advanced | E2: =IF($D2="","",IF($D2="Basic",0.2,IF($D2="Developing",0.5,IF($D2="Advanced",0.8,IF($D2="Frontier",1,""))))) | F2: E3
A3: FRONTEND | B3: UX_NAVIGATION | C3: Yes | D3: Advanced | E3: =IF($D3="","",IF($D3="Basic",0.2,IF($D3="Developing",0.5,IF($D3="Advanced",0.8,IF($D3="Frontier",1,""))))) | F3: E4
A4: FRONTEND | B4: DEVICE_COVERAGE | D4: Developing | E4: =IF($D4="","",IF($D4="Basic",0.2,IF($D4="Developing",0.5,IF($D4="Advanced",0.8,IF($D4="Frontier",1,""))))) | F4: E2
A5: FRONTEND | B5: PERSONALISATION | D5: Developing | E5: =IF($D5="","",IF($D5="Basic",0.2,IF($D5="Developing",0.5,IF($D5="Advanced",0.8,IF($D5="Frontier",1,""))))) | F5: E2
A6: FRONTEND | B6: ACCESSIBILITY_LOCALISATION | D6: Basic | E6: =IF($D6="","",IF($D6="Basic",0.2,IF($D6="Developing",0.5,IF($D6="Advanced",0.8,IF($D6="Frontier",1,""))))) | F6: E2
A7: FRONTEND | B7: EXPERIMENTATION_ANALYTICS | D7: Developing | E7: =IF($D7="","",IF($D7="Basic",0.2,IF($D7="Developing",0.5,IF($D7="Advanced",0.8,IF($D7="Frontier",1,""))))) | F7: E3
A8: APP_SERVER | B8: HOSTING_ELASTICITY | D8: Advanced | E8: =IF($D8="","",IF($D8="Basic",0.2,IF($D8="Developing",0.5,IF($D8="Advanced",0.8,IF($D8="Frontier",1,""))))) | F8: E3
A9: APP_SERVER | B9: RESILIENCE_DR | C9: Yes | D9: Developing | E9: =IF($D9="","",IF($D9="Basic",0.2,IF($D9="Developing",0.5,IF($D9="Advanced",0.8,IF($D9="Frontier",1,""))))) | F9: E3
A10: APP_SERVER | B10: API_DESIGN | D10: Advanced | E10: =IF($D10="","",IF($D10="Basic",0.2,IF($D10="Developing",0.5,IF($D10="Advanced",0.8,IF($D10="Frontier",1,""))))) | F10: E3
A11: APP_SERVER | B11: SECURITY_COMPLIANCE | C11: Yes | D11: Advanced | E11: =IF($D11="","",IF($D11="Basic",0.2,IF($D11="Developing",0.5,IF($D11="Advanced",0.8,IF($D11="Frontier",1,""))))) | F11: E4
A12: APP_SERVER | B12: DEVOPS_DEPLOYMENT | D12: Developing | E12: =IF($D12="","",IF($D12="Basic",0.2,IF($D12="Developing",0.5,IF($D12="Advanced",0.8,IF($D12="Frontier",1,""))))) | F12: E2
A13: APP_SERVER | B13: DATA_ARCHITECTURE | D13: Developing | E13: =IF($D13="","",IF($D13="Basic",0.2,IF($D13="Developing",0.5,IF($D13="Advanced",0.8,IF($D13="Frontier",1,""))))) | F13: E2
A14: APP_SERVER | B14: OBSERVABILITY | D14: Advanced | E14: =IF($D14="","",IF($D14="Basic",0.2,IF($D14="Developing",0.5,IF($D14="Advanced",0.8,IF($D14="Frontier",1,""))))) | F14: E3
A15: MARKET_DATA | B15: EXCHANGE_COVERAGE | D15: Advanced | E15: =IF($D15="","",IF($D15="Basic",0.2,IF($D15="Developing",0.5,IF($D15="Advanced",0.8,IF($D15="Frontier",1,""))))) | F15: E3
A16: MARKET_DATA | B16: INSTRUMENT_UNIVERSE | D16: Advanced | E16: =IF($D16="","",IF($D16="Basic",0.2,IF($D16="Developing",0.5,IF($D16="Advanced",0.8,IF($D16="Frontier",1,""))))) | F16: E2
A17: MARKET_DATA | B17: DATA_DEPTH_QUALITY | C17: Yes | D17: Advanced | E17: =IF($D17="","",IF($D17="Basic",0.2,IF($D17="Developing",0.5,IF($D17="Advanced",0.8,IF($D17="Frontier",1,""))))) | F17: E3
A18: MARKET_DATA | B18: LATENCY_TIMELINESS | C18: Yes | D18: Developing | E18: =IF($D18="","",IF($D18="Basic",0.2,IF($D18="Developing",0.5,IF($D18="Advanced",0.8,IF($D18="Frontier",1,""))))) | F18: E3
A19: MARKET_DATA | B19: HISTORY_DEPTH | D19: Developing | E19: =IF($D19="","",IF($D19="Basic",0.2,IF($D19="Developing",0.5,IF($D19="Advanced",0.8,IF($D19="Frontier",1,""))))) | F19: E2
A20: MARKET_DATA | B20: VENDOR_REDUNDANCY | D20: Basic | E20: =IF($D20="","",IF($D20="Basic",0.2,IF($D20="Developing",0.5,IF($D20="Advanced",0.8,IF($D20="Frontier",1,""))))) | F20: E2
A21: MARKET_DATA | B21: VALUE_ADD_SERVICES | E21: =IF($D21="","",IF($D21="Basic",0.2,IF($D21="Developing",0.5,IF($D21="Advanced",0.8,IF($D21="Frontier",1,""))))) | G21: NOT_ASSESSED
A22: ORCHESTRATION | B22: WORKFLOW_ENGINE | C22: Yes | D22: Developing | E22: =IF($D22="","",IF($D22="Basic",0.2,IF($D22="Developing",0.5,IF($D22="Advanced",0.8,IF($D22="Frontier",1,""))))) | F22: E3
A23: ORCHESTRATION | B23: ROUTING_LOGIC | D23: Developing | E23: =IF($D23="","",IF($D23="Basic",0.2,IF($D23="Developing",0.5,IF($D23="Advanced",0.8,IF($D23="Frontier",1,""))))) | F23: E2
A24: ORCHESTRATION | B24: EVENT_DRIVEN | D24: Basic | E24: =IF($D24="","",IF($D24="Basic",0.2,IF($D24="Developing",0.5,IF($D24="Advanced",0.8,IF($D24="Frontier",1,""))))) | F24: E2
A25: ORCHESTRATION | B25: CONFIG_VS_CODE | D25: Developing | E25: =IF($D25="","",IF($D25="Basic",0.2,IF($D25="Developing",0.5,IF($D25="Advanced",0.8,IF($D25="Frontier",1,""))))) | F25: E2
A26: ORCHESTRATION | B26: ORCH_MONITORING | D26: Developing | E26: =IF($D26="","",IF($D26="Basic",0.2,IF($D26="Developing",0.5,IF($D26="Advanced",0.8,IF($D26="Frontier",1,""))))) | F26: E3
A27: CMS | B27: RESEARCH_AUTHORING | D27: Advanced | E27: =IF($D27="","",IF($D27="Basic",0.2,IF($D27="Developing",0.5,IF($D27="Advanced",0.8,IF($D27="Frontier",1,""))))) | F27: E3
A28: CMS | B28: RESEARCH_DISTRIBUTION | D28: Developing | E28: =IF($D28="","",IF($D28="Basic",0.2,IF($D28="Developing",0.5,IF($D28="Advanced",0.8,IF($D28="Frontier",1,""))))) | F28: E2
A29: CMS | B29: EMAIL_CAMPAIGNS | D29: Advanced | E29: =IF($D29="","",IF($D29="Basic",0.2,IF($D29="Developing",0.5,IF($D29="Advanced",0.8,IF($D29="Frontier",1,""))))) | F29: E3
A30: CMS | B30: CRM_MODEL | C30: Yes | D30: Developing | E30: =IF($D30="","",IF($D30="Basic",0.2,IF($D30="Developing",0.5,IF($D30="Advanced",0.8,IF($D30="Frontier",1,""))))) | F30: E3
A31: CMS | B31: STATEMENTS | D31: Advanced | E31: =IF($D31="","",IF($D31="Basic",0.2,IF($D31="Developing",0.5,IF($D31="Advanced",0.8,IF($D31="Frontier",1,""))))) | F31: E3
A32: CMS | B32: CONTENT_SEARCH_PERSONALISATION | D32: Basic | E32: =IF($D32="","",IF($D32="Basic",0.2,IF($D32="Developing",0.5,IF($D32="Advanced",0.8,IF($D32="Frontier",1,""))))) | F32: E2
A33: BACKOFFICE | B33: CUSTODY | C33: Yes | D33: Advanced | E33: =IF($D33="","",IF($D33="Basic",0.2,IF($D33="Developing",0.5,IF($D33="Advanced",0.8,IF($D33="Frontier",1,""))))) | F33: E4
A34: BACKOFFICE | B34: PAYMENTS_FUNDING | D34: Advanced | E34: =IF($D34="","",IF($D34="Basic",0.2,IF($D34="Developing",0.5,IF($D34="Advanced",0.8,IF($D34="Frontier",1,""))))) | F34: E3
A35: BACKOFFICE | B35: KYC_ONBOARDING | D35: Advanced | E35: =IF($D35="","",IF($D35="Basic",0.2,IF($D35="Developing",0.5,IF($D35="Advanced",0.8,IF($D35="Frontier",1,""))))) | F35: E3
A36: BACKOFFICE | B36: PORTFOLIO_MGMT | D36: Developing | E36: =IF($D36="","",IF($D36="Basic",0.2,IF($D36="Developing",0.5,IF($D36="Advanced",0.8,IF($D36="Frontier",1,""))))) | F36: E2
A37: BACKOFFICE | B37: CREDIT_RISK | D37: Developing | E37: =IF($D37="","",IF($D37="Basic",0.2,IF($D37="Developing",0.5,IF($D37="Advanced",0.8,IF($D37="Frontier",1,""))))) | F37: E2
A38: BACKOFFICE | B38: REG_REPORTING | C38: Yes | D38: Advanced | E38: =IF($D38="","",IF($D38="Basic",0.2,IF($D38="Developing",0.5,IF($D38="Advanced",0.8,IF($D38="Frontier",1,""))))) | F38: E4
A39: OEMS | B39: ASSET_COVERAGE | D39: Developing | E39: =IF($D39="","",IF($D39="Basic",0.2,IF($D39="Developing",0.5,IF($D39="Advanced",0.8,IF($D39="Frontier",1,""))))) | F39: E2
A40: OEMS | B40: EXEC_ALGOS | D40: Basic | E40: =IF($D40="","",IF($D40="Basic",0.2,IF($D40="Developing",0.5,IF($D40="Advanced",0.8,IF($D40="Frontier",1,""))))) | F40: E2
...

Sheet Modules
A1: Module | B1: alpha | C1: weighted_avg | D1: min_term | E1: q_m | F1: gate_band | G1: gate_blocked | H1: coverage
A2: FRONTEND | B2: 0.7 | C2: =IFERROR(AVERAGE(Subcomponents!$E$2:$E$7),"") | D2: =MIN(Subcomponents!$E$2:$E$7) | E2: =$B2*$C2+(1-$B2)*$D2 | F2: Developing | H2: =IFERROR(COUNT(Subcomponents!$E$2:$E$7)/(COUNT(Subcomponents!$E$2:$E$7)+COUNTIF(Subcomponents!$G$2:$G$7,"NOT_ASSESSED")),"")
A3: APP_SERVER | B3: 0.7 | C3: =IFERROR(AVERAGE(Subcomponents!$E$8:$E$14),"") | D3: =MIN(Subcomponents!$E$8:$E$14) | E3: =$B3*$C3+(1-$B3)*$D3 | F3: Advanced | H3: =IFERROR(COUNT(Subcomponents!$E$8:$E$14)/(COUNT(Subcomponents!$E$8:$E$14)+COUNTIF(Subcomponents!$G$8:$G$14,"NOT_ASSESSED")),"")
A4: MARKET_DATA | B4: 0.7 | C4: =IFERROR(AVERAGE(Subcomponents!$E$15:$E$21),"") | D4: =MIN(Subcomponents!$E$15:$E$21) | E4: =$B4*$C4+(1-$B4)*$D4 | F4: Developing | H4: =IFERROR(COUNT(Subcomponents!$E$15:$E$21)/(COUNT(Subcomponents!$E$15:$E$21)+COUNTIF(Subcomponents!$G$15:$G$21,"NOT_ASSESSED")),"")
A5: ORCHESTRATION | B5: 0.7 | C5: =IFERROR(AVERAGE(Subcomponents!$E$22:$E$26),"") | D5: =MIN(Subcomponents!$E$22:$E$26) | E5: =$B5*$C5+(1-$B5)*$D5 | F5: Developing | H5: =IFERROR(COUNT(Subcomponents!$E$22:$E$26)/(COUNT(Subcomponents!$E$22:$E$26)+COUNTIF(Subcomponents!$G$22:$G$26,"NOT_ASSESSED")),"")
A6: CMS | B6: 0.7 | C6: =IFERROR(AVERAGE(Subcomponents!$E$27:$E$32),"") | D6: =MIN(Subcomponents!$E$27:$E$32) | E6: =$B6*$C6+(1-$B6)*$D6 | F6: Developing | H6: =IFERROR(COUNT(Subcomponents!$E$27:$E$32)/(COUNT(Subcomponents!$E$27:$E$32)+COUNTIF(Subcomponents!$G$27:$G$32,"NOT_ASSESSED")),"")
A7: BACKOFFICE | B7: 0.7 | C7: =IFERROR(AVERAGE(Subcomponents!$E$33:$E$38),"") | D7: =MIN(Subcomponents!$E$33:$E$38) | E7: =$B7*$C7+(1-$B7)*$D7 | F7: Advanced | H7: =IFERROR(COUNT(Subcomponents!$E$33:$E$38)/(COUNT(Subcomponents!$E$33:$E$38)+COUNTIF(Subcomponents!$G$33:$G$38,"NOT_ASSESSED")),"")
A8: OEMS | B8: 0.7 | C8: =IFERROR(AVERAGE(Subcomponents!$E$39:$E$44),"") | D8: =MIN(Subcomponents!$E$39:$E$44) | E8: =$B8*$C8+(1-$B8)*$D8 | F8: Developing | H8: =IFERROR(COUNT(Subcomponents!$E$39:$E$44)/(COUNT(Subcomponents!$E$39:$E$44)+COUNTIF(Subcomponents!$G$39:$G$44,"NOT_ASSESSED")),"")
A9: EMS_GATEWAY | B9: 0.7 | C9: =IFERROR(AVERAGE(Subcomponents!$E$45:$E$48),"") | D9: =MIN(Subcomponents!$E$45:$E$48) | E9: =$B9*$C9+(1-$B9)*$D9 | F9: Advanced | H9: =IFERROR(COUNT(Subcomponents!$E$45:$E$48)/(COUNT(Subcomponents!$E$45:$E$48)+COUNTIF(Subcomponents!$G$45:$G$48,"NOT_ASSESSED")),"")
A10: LIQ_CONNECT | B10: 0.7 | C10: =IFERROR(AVERAGE(Subcomponents!$E$49:$E$52),"") | D10: =MIN(Subcomponents!$E$49:$E$52) | E10: =$B10*$C10+(1-$B10)*$D10 | F10: Advanced | H10: =IFERROR(COUNT(Subcomponents!$E$49:$E$52)/(COUNT(Subcomponents!$E$49:$E$52)+COUNTIF(Subcomponents!$G$49:$G$52,"NOT_ASSESSED")),"")

Sheet Business
A1: Metric | B1: Raw | C1: Unit | D1: Direction | E1: x1 | F1: x2 | G1: x3 | H1: x4 | I1: y1 | J1: y2 | K1: y3 | L1: y4 | M1: n_k
A2: AUA | B2: 1800000000 | C2: GBP | D2: higher_is_better | E2: 0 | F2: 250000000 | G2: 2000000000 | H2: 20000000000 | I2: 0.2 | J2: 0.5 | K2: 0.8 | L2: 1 | M2: =IF($B2<=$E2,$I2,IF($B2>=$H2,$L2,IF($B2<=$F2,$I2+($B2-$E2)/($F2-$E2)*($J2-$I2),IF($B2<=$G2,$J2+($B2-$F2)/($G2-$F2)*($K2-$J2),$K2+($B2-$G2)/($H2-$G2)*($L2-$K2))))))
A3: ACTIVE_CLIENTS | B3: 180000 | C3: count | D3: higher_is_better | E3: 0 | F3: 25000 | G3: 250000 | H3: 2000000 | I3: 0.2 | J3: 0.5 | K3: 0.8 | L3: 1 | M3: =IF($B3<=$E3,$I3,IF($B3>=$H3,$L3,IF($B3<=$F3,$I3+($B3-$E3)/($F3-$E3)*($J3-$I3),IF($B3<=$G3,$J3+($B3-$F3)/($G3-$F3)*($K3-$J3),$K3+($B3-$G3)/($H3-$G3)*($L3-$K3))))))
A4: NET_REVENUE | B4: 85000000 | C4: GBP | D4: higher_is_better | E4: 0 | F4: 10000000 | G4: 100000000 | H4: 1000000000 | I4: 0.2 | J4: 0.5 | K4: 0.8 | L4: 1 | M4: =IF($B4<=$E4,$I4,IF($B4>=$H4,$L4,IF($B4<=$F4,$I4+($B4-$E4)/($F4-$E4)*($J4-$I4),IF($B4<=$G4,$J4+($B4-$F4)/($G4-$F4)*($K4-$J4),$K4+($B4-$G4)/($H4-$G4)*($L4-$K4))))))
A5: REVENUE_PER_CLIENT | B5: 472 | C5: GBP_per_year | D5: higher_is_better | E5: 50 | F5: 200 | G5: 600 | H5: 2000 | I5: 0.2 | J5: 0.5 | K5: 0.8 | L5: 1 | M5: =IF($B5<=$E5,$I5,IF($B5>=$H5,$L5,IF($B5<=$F5,$I5+($B5-$E5)/($F5-$E5)*($J5-$I5),IF($B5<=$G5,$J5+($B5-$F5)/($G5-$F5)*($K5-$J5),$K5+($B5-$G5)/($H5-$G5)*($L5-$K5))))))
A6: GROSS_MARGIN | B6: 58 | C6: percent | D6: higher_is_better | E6: 20 | F6: 45 | G6: 65 | H6: 80 | I6: 0.2 | J6: 0.5 | K6: 0.8 | L6: 1 | M6: =IF($B6<=$E6,$I6,IF($B6>=$H6,$L6,IF($B6<=$F6,$I6+($B6-$E6)/($F6-$E6)*($J6-$I6),IF($B6<=$G6,$J6+($B6-$F6)/($G6-$F6)*($K6-$J6),$K6+($B6-$G6)/($H6-$G6)*($L6-$K6))))))
A7: COST_TO_SERVE | B7: 140 | C7: GBP_per_year | D7: lower_is_better | E7: 40 | F7: 100 | G7: 200 | H7: 400 | I7: 1 | J7: 0.8 | K7: 0.5 | L7: 0.2 | M7: =IF($B7<=$E7,$I7,IF($B7>=$H7,$L7,IF($B7<=$F7,$I7+($B7-$E7)/($F7-$E7)*($J7-$I7),IF($B7<=$G7,$J7+($B7-$F7)/($G7-$F7)*($K7-$J7),$K7+($B7-$G7)/($H7-$G7)*($L7-$K7))))))
A8: NET_REVENUE_RETENTION | B8: 104 | C8: percent | D8: higher_is_better | E8: 80 | F8: 100 | G8: 110 | H8: 130 | I8: 0.2 | J8: 0.5 | K8: 0.8 | L8: 1 | M8: =IF($B8<=$E8,$I8,IF($B8>=$H8,$L8,IF($B8<=$F8,$I8+($B8-$E8)/($F8-$E8)*($J8-$I8),IF($B8<=$G8,$J8+($B8-$F8)/($G8-$F8)*($K8-$J8),$K8+($B8-$G8)/($H8-$G8)*($L8-$K8))))))
A9: CLIENT_GROWTH_RATE | B9: 14 | C9: percent | D9: higher_is_better | E9: 0 | F9: 10 | G9: 25 | H9: 50 | I9: 0.2 | J9: 0.5 | K9: 0.8 | L9: 1 | M9: =IF($B9<=$E9,$I9,IF($B9>=$H9,$L9,IF($B9<=$F9,$I9+($B9-$E9)/($F9-$E9)*($J9-$I9),IF($B9<=$G9,$J9+($B9-$F9)/($G9-$F9)*($K9-$J9),$K9+($B9-$G9)/($H9-$G9)*($L9-$K9))))))
A10: TAKE_RATE_DURABILITY | B10: 22 | C10: bps | D10: higher_is_better | E10: 5 | F10: 15 | G10: 30 | H10: 60 | I10: 0.2 | J10: 0.5 | K10: 0.8 | L10: 1 | M10: =IF($B10<=$E10,$I10,IF($B10>=$H10,$L10,IF($B10<=$F10,$I10+($B10-$E10)/($F10-$E10)*($J10-$I10),IF($B10<=$G10,$J10+($B10-$F10)/($G10-$F10)*($K10-$J10),$K10+($B10-$G10)/($H10-$G10)*($L10-$K10))))))
A11: CAC_PAYBACK_MONTHS | B11: 18 | C11: months | D11: lower_is_better | E11: 6 | F11: 12 | G11: 24 | H11: 48 | I11: 1 | J11: 0.8 | K11: 0.5 | L11: 0.2 | M11: =IF($B11<=$E11,$I11,IF($B11>=$H11,$L11,IF($B11<=$F11,$I11+($B11-$E11)/($F11-$E11)*($J11-$I11),IF($B11<=$G11,$J11+($B11-$F11)/($G11-$F11)*($K11-$J11),$K11+($B11-$G11)/($H11-$G11)*($L11-$K11))))))
L12: B = | M12: =AVERAGE($M$2:$M$11)

Sheet Powers
A1: Power | B1: Strength | C1: Value
A2: SCALE_ECONOMIES | B2: Emerging | C2: =IF($B2="None",0,IF($B2="Emerging",0.4,IF($B2="Established",0.7,IF($B2="Wide",1,""))))
A3: NETWORK_ECONOMIES | B3: None | C3: =IF($B3="None",0,IF($B3="Emerging",0.4,IF($B3="Established",0.7,IF($B3="Wide",1,""))))
A4: COUNTER_POSITIONING | B4: None | C4: =IF($B4="None",0,IF($B4="Emerging",0.4,IF($B4="Established",0.7,IF($B4="Wide",1,""))))
A5: SWITCHING_COSTS | B5: Established | C5: =IF($B5="None",0,IF($B5="Emerging",0.4,IF($B5="Established",0.7,IF($B5="Wide",1,""))))
A6: BRANDING | B6: Emerging | C6: =IF($B6="None",0,IF($B6="Emerging",0.4,IF($B6="Established",0.7,IF($B6="Wide",1,""))))
A7: CORNERED_RESOURCE | B7: None | C7: =IF($B7="None",0,IF($B7="Emerging",0.4,IF($B7="Established",0.7,IF($B7="Wide",1,""))))
A8: PROCESS_POWER | B8: Emerging | C8: =IF($B8="None",0,IF($B8="Emerging",0.4,IF($B8="Established",0.7,IF($B8="Wide",1,""))))
B9: P = | C9: =AVERAGE($C$2:$C$8)

Sheet Composite
A1: ATLAS Composite — V = θ_B·B + θ_P·P + θ_L·L
A2: Item | B2: Coefficient | C2: Value
A3: alpha_L | B3: 0.7
A4: L weighted term (mean q_m) | C4: =AVERAGE(Modules!$E$2,Modules!$E$3,Modules!$E$4,Modules!$E$5,Modules!$E$6,Modules!$E$7,Modules!$E$8,Modules!$E$9,Modules!$E$10)
A5: L min term (critical modules) | C5: =MIN(Modules!$E$3,Modules!$E$7,Modules!$E$8)
A6: L | C6: =$B3*$C4+(1-$B3)*$C5
A7: B | C7: =Business!$M$12
A8: P | C8: =Powers!$C$9
A9: theta_B | B9: 0.3
A10: theta_P | B10: 0.3
A11: theta_L | B11: 0.4
A12: V | C12: =$B9*$C7+$B10*$C8+$B11*$C6
A13: V (display 0–100) | C13: =$C12*100
